<?xml version="1.0"?>
<robot name="my_robot" xmlns:xacro="http://www.ros.org/wiki/xacro">

  <!-- Base -->
  <link name="base_link">
    <visual>
      <geometry>
        <box size="0.4 0.3 0.1"/>
      </geometry>
    </visual>
    <collision>
      <geometry>
        <box size="0.4 0.3 0.1"/>
      </geometry>
    </collision>
    <inertial>
      <mass value="5.0"/>
      <origin xyz="0 0 0"/>
      <inertia ixx="0.1" iyy="0.1" izz="0.1"
               ixy="0.0" ixz="0.0" iyz="0.0"/>
    </inertial>
  </link>

  <!-- Left Wheel -->
  <link name="left_wheel">
    <visual>
        <origin rpy="1.5708 0 0"/>
        <geometry>
        <cylinder radius="0.1" length="0.02"/>
        </geometry>
        <material name="black">
        <color rgba="0.1 0.1 0.1 1.0"/>
        </material>
    </visual>
  </link>


  <!-- Right Wheel -->
  <link name="right_wheel">
    <visual>
        <origin rpy="1.5708 0 0"/>
        <geometry>
        <cylinder radius="0.1" length="0.02"/>
        </geometry>
        <material name="black">
        <color rgba="0.1 0.1 0.1 1.0"/>
        </material>
    </visual>
  </link>

  <!-- Joints -->
<joint name="left_wheel_joint" type="continuous">
  <parent link="base_link"/>
  <child link="left_wheel"/>
  <origin xyz="0 0.175 0"/>
  <axis xyz="0 1 0"/>
</joint>

  <joint name="right_wheel_joint" type="continuous">
    <parent link="base_link"/>
    <child link="right_wheel"/>
    <origin xyz="0 -0.175 0"/>
    <axis xyz="0 1 0"/>
  </joint>

<gazebo>
  <plugin
    filename="libgz_ros2_control-system.so"
    name="gz_ros2_control::GazeboSystem">
  </plugin>
</gazebo>

</robot>
